[34m[1mwandb[0m: [32m[41mERROR[0m failed to find artifact collection VAE_MNIST_128 (Error 404: Not Found)
Traceback (most recent call last):
  File "/opt/conda/lib/python3.10/site-packages/wandb/apis/normalize.py", line 25, in wrapper
    return func(*args, **kwargs)
  File "/opt/conda/lib/python3.10/site-packages/wandb/apis/public/api.py", line 1210, in _artifact
    artifact = wandb.Artifact._from_name(
  File "/opt/conda/lib/python3.10/site-packages/wandb/sdk/artifacts/artifact.py", line 270, in _from_name
    response = client.execute(
  File "/opt/conda/lib/python3.10/site-packages/wandb/sdk/lib/retry.py", line 212, in wrapped_fn
    return retrier(*args, **kargs)
  File "/opt/conda/lib/python3.10/site-packages/wandb/sdk/lib/retry.py", line 131, in __call__
    result = self._call_fn(*args, **kwargs)
  File "/opt/conda/lib/python3.10/site-packages/wandb/apis/public/api.py", line 72, in execute
    return self._client.execute(*args, **kwargs)
  File "/opt/conda/lib/python3.10/site-packages/wandb/vendor/gql-0.2.0/wandb_gql/client.py", line 52, in execute
    result = self._get_result(document, *args, **kwargs)
  File "/opt/conda/lib/python3.10/site-packages/wandb/vendor/gql-0.2.0/wandb_gql/client.py", line 60, in _get_result
    return self.transport.execute(document, *args, **kwargs)
  File "/opt/conda/lib/python3.10/site-packages/wandb/sdk/lib/gql_request.py", line 59, in execute
    request.raise_for_status()
  File "/opt/conda/lib/python3.10/site-packages/requests/models.py", line 953, in raise_for_status
    raise HTTPError(http_error_msg, response=self)
requests.exceptions.HTTPError: 404 Client Error: Not Found for url: https://api.wandb.ai/graphql

During handling of the above exception, another exception occurred:

Traceback (most recent call last):
  File "/root/default/Generative-Model/VAE/inference.py", line 130, in <module>
    main()
  File "/root/default/Generative-Model/VAE/inference.py", line 67, in main
    artifact = wandb.use_artifact(
  File "/opt/conda/lib/python3.10/site-packages/wandb/sdk/wandb_run.py", line 403, in wrapper_fn
    return func(self, *args, **kwargs)
  File "/opt/conda/lib/python3.10/site-packages/wandb/sdk/wandb_run.py", line 393, in wrapper
    return func(self, *args, **kwargs)
  File "/opt/conda/lib/python3.10/site-packages/wandb/sdk/wandb_run.py", line 3071, in use_artifact
    artifact = public_api._artifact(type=type, name=name)
  File "/opt/conda/lib/python3.10/site-packages/wandb/apis/normalize.py", line 35, in wrapper
    raise CommError(message, error)
wandb.errors.errors.CommError: failed to find artifact collection VAE_MNIST_128 (Error 404: Not Found)
