Traceback (most recent call last):
  File "/root/default/Generative-Model/GAN/inference.py", line 132, in <module>
    main()
  File "/root/default/Generative-Model/GAN/inference.py", line 72, in main
    base_name = f"{config['dataset']}_{config['lr']}_{config['batch_size']}_{config['alpha']}_{config['beta']}"
KeyError: 'alpha'
